Workbook

Sheet SUMMRY
A1: ADVANDE FOR THE MONTH OF AUGUST 2026
A3: Sr. No. | B3: DEPARTMENT | C3: S RATE | D3: DAYS | E3: AMOUNT | F3: HOURS | G3: AMOUNT | H3: G SALARY | I3: ADVANCE | J3: ADVANCE | K3: LOAN DED. | L3: SUITE DED. | M3: NET PAY
A4: 1 | B4: =+Sheet1!C3 -> 01-ADMINISTRAION | C4: =+Sheet1!D20 -> 558955 | D4: =+Sheet1!E20 -> 0 | E4: =+Sheet1!F20 -> 0 | F4: =+Sheet1!G20 -> 0 | G4: =+Sheet1!H20 -> 0 | H4: =+Sheet1!I20 -> 0 | I4: =+Sheet1!J20 -> 0 | J4: =+Sheet1!K20 -> 0 | ... M4: =+Sheet1!N20 -> 0
A5: 2 | B5: =+Sheet1!C23 -> 02- ACCOUNT | C5: =+Sheet1!D35 -> 685799 | D5: =+Sheet1!E35 -> 0 | E5: =+Sheet1!F35 -> 0 | F5: =+Sheet1!G35 -> 0 | G5: =+Sheet1!H35 -> 0 | H5: =+Sheet1!I35 -> 0 | I5: =+Sheet1!J35 -> 0 | J5: =+Sheet1!K35 -> 0 | ... M5: =+Sheet1!N35 -> 0
A6: 3 | B6: =+Sheet1!C41 -> 03-KORA | C6: =+Sheet1!D51 -> 326990 | D6: =+Sheet1!E51 -> 0 | E6: =+Sheet1!F51 -> 0 | F6: =+Sheet1!G51 -> 0 | G6: =+Sheet1!H51 -> 0 | H6: =+Sheet1!I51 -> 0 | I6: =+Sheet1!J51 -> 0 | J6: =+Sheet1!K51 -> 0 | ... M6: =+Sheet1!N51 -> 0
A7: 4 | B7: =+Sheet1!C58 -> 04-TAYYAR STORE | C7: =+Sheet1!D72 -> 461880 | D7: =+Sheet1!E72 -> 0 | E7: =+Sheet1!F72 -> 0 | F7: =+Sheet1!G72 -> 0 | G7: =+Sheet1!H72 -> 0 | H7: =+Sheet1!I72 -> 0 | I7: =+Sheet1!J72 -> 0 | J7: =+Sheet1!K72 -> 0 | ... M7: =+Sheet1!N72 -> 0
A8: 5 | B8: =+Sheet1!C79 -> 05-ELECTRIC | C8: =+Sheet1!D90 -> 453320 | D8: =+Sheet1!E90 -> 0 | E8: =+Sheet1!F90 -> 0 | F8: =+Sheet1!G90 -> 0 | G8: =+Sheet1!H90 -> 0 | H8: =+Sheet1!I90 -> 0 | I8: =+Sheet1!J90 -> 0 | J8: =+Sheet1!K90 -> 0 | ... M8: =+Sheet1!N90 -> 0
A9: 6 | B9: =+Sheet1!C95 -> 06-WORK SHOP | C9: =+Sheet1!D106 -> 446900 | D9: =+Sheet1!E106 -> 0 | E9: =+Sheet1!F106 -> 0 | F9: =+Sheet1!G106 -> 0 | G9: =+Sheet1!H106 -> 0 | H9: =+Sheet1!I106 -> 0 | I9: =+Sheet1!J106 -> 0 | J9: =+Sheet1!K106 -> 0 | ... M9: =+Sheet1!N106 -> 0
A10: 7 | B10: =+Sheet1!C116 -> 07-CREATION | C10: =+Sheet1!D137 -> 1593500 | D10: =+Sheet1!E137 -> 0 | E10: =+Sheet1!F137 -> 0 | F10: =+Sheet1!G137 -> 0 | G10: =+Sheet1!H137 -> 0 | H10: =+Sheet1!I137 -> 0 | I10: =+Sheet1!J137 -> 0 | J10: =+Sheet1!K137 -> 0 | ... M10: =+Sheet1!N137 -> 0
A11: 8 | B11: =+Sheet1!C151 -> 08-KARE | C11: =+Sheet1!D174 -> 889830 | D11: =+Sheet1!E174 -> 0 | E11: =+Sheet1!F174 -> 0 | F11: =+Sheet1!G174 -> 0 | G11: =+Sheet1!H174 -> 0 | H11: =+Sheet1!I174 -> 0 | I11: =+Sheet1!J174 -> 0 | J11: =+Sheet1!K174 -> 0 | ... M11: =+Sheet1!N174 -> 0
A12: 9 | B12: =+Sheet1!C176 -> 09-SINGING | C12: =+Sheet1!D185 -> 209000 | D12: =+Sheet1!E185 -> 0 | E12: =+Sheet1!F185 -> 0 | F12: =+Sheet1!G185 -> 0 | G12: =+Sheet1!H185 -> 0 | H12: =+Sheet1!I185 -> 0 | I12: =+Sheet1!J185 -> 0 | J12: =+Sheet1!K185 -> 0 | ... M12: =+Sheet1!N185 -> 0
A13: 10 | B13: =+Sheet1!C187 -> 10-KARA DRAWING | C13: =+Sheet1!D205 -> 432310 | D13: =+Sheet1!E205 -> 0 | E13: =+Sheet1!F205 -> 0 | F13: =+Sheet1!G205 -> 0 | G13: =+Sheet1!H205 -> 0 | H13: =+Sheet1!I205 -> 0 | I13: =+Sheet1!J205 -> 0 | J13: =+Sheet1!K205 -> 0 | ... M13: =+Sheet1!N205 -> 0
A14: 11 | B14: =+Sheet1!C220 -> 11-MERCRIZE | C14: =+Sheet1!D236 -> 478750 | D14: =+Sheet1!E236 -> 0 | E14: =+Sheet1!F236 -> 0 | F14: =+Sheet1!G236 -> 0 | G14: =+Sheet1!H236 -> 0 | H14: =+Sheet1!I236 -> 0 | I14: =+Sheet1!J236 -> 0 | J14: =+Sheet1!K236 -> 0 | ... M14: =+Sheet1!N236 -> 0
A15: 12 | B15: =+Sheet1!C257 -> 12-BOUZER | C15: =+Sheet1!D271 -> 498410 | D15: =+Sheet1!E271 -> 0 | E15: =+Sheet1!F271 -> 0 | F15: =+Sheet1!G271 -> 0 | G15: =+Sheet1!H271 -> 0 | H15: =+Sheet1!I271 -> 0 | I15: =+Sheet1!J271 -> 0 | J15: =+Sheet1!K271 -> 0 | ... M15: =+Sheet1!N271 -> 0
A16: 13 | B16: =+Sheet1!C278 -> 13-ENGRAVING | C16: =+Sheet1!D286 -> 272650 | D16: =+Sheet1!E286 -> 0 | E16: =+Sheet1!F286 -> 0 | F16: =+Sheet1!G286 -> 0 | G16: =+Sheet1!H286 -> 0 | H16: =+Sheet1!I286 -> 0 | I16: =+Sheet1!J286 -> 0 | J16: =+Sheet1!K286 -> 0 | ... M16: =+Sheet1!N286 -> 0
A17: 14 | B17: =+Sheet1!C293 -> 14-COLOR | C17: =+Sheet1!D303 -> 434640 | D17: =+Sheet1!E303 -> 0 | E17: =+Sheet1!F303 -> 0 | F17: =+Sheet1!G303 -> 0 | G17: =+Sheet1!H303 -> 0 | H17: =+Sheet1!I303 -> 0 | I17: =+Sheet1!J303 -> 0 | J17: =+Sheet1!K303 -> 0 | ... M17: =+Sheet1!N303 -> 0
A18: 15 | B18: =+Sheet1!C329 -> 15- SUNTEX | C18: =+Sheet1!D346 -> 767400 | D18: =+Sheet1!E346 -> 0 | E18: =+Sheet1!F346 -> 0 | F18: =+Sheet1!G346 -> 0 | G18: =+Sheet1!H346 -> 0 | H18: =+Sheet1!I346 -> 0 | I18: =+Sheet1!J346 -> 0 | J18: =+Sheet1!K346 -> 0 | ... M18: =+Sheet1!N346 -> 0
A19: 16 | B19: =+Sheet1!C349 -> 17- DIGITAL MANDI MAN | C19: =+Sheet1!D355 -> 123500 | D19: =+Sheet1!E355 -> 0 | E19: =+Sheet1!F355 -> 0 | F19: =+Sheet1!G355 -> 0 | G19: =+Sheet1!H355 -> 0 | H19: =+Sheet1!I355 -> 0 | I19: =+Sheet1!J355 -> 0 | J19: =+Sheet1!K355 -> 0 | ... M19: =+Sheet1!N355 -> 0
A20: 17 | B20: =+Sheet1!C364 -> 18-AUTO 01 | C20: =+Sheet1!D383 -> 494510 | D20: =+Sheet1!E383 -> 0 | E20: =+Sheet1!F383 -> 0 | F20: =+Sheet1!G383 -> 0 | G20: =+Sheet1!H383 -> 0 | H20: =+Sheet1!I383 -> 0 | I20: =+Sheet1!J383 -> 0 | J20: =+Sheet1!K383 -> 0 | ... M20: =+Sheet1!N383 -> 0
A21: 18 | B21: =+Sheet1!C400 -> 19- AUTO 02 | C21: =+Sheet1!D421 -> 594290 | D21: =+Sheet1!E421 -> 0 | E21: =+Sheet1!F421 -> 0 | F21: =+Sheet1!G421 -> 0 | G21: =+Sheet1!H421 -> 0 | H21: =+Sheet1!I421 -> 0 | I21: =+Sheet1!J421 -> 0 | J21: =+Sheet1!K421 -> 0 | ... M21: =+Sheet1!N421 -> 0
A22: 19 | B22: =+Sheet1!C436 -> 20-CALANDER | C22: =+Sheet1!D455 -> 535975 | D22: =+Sheet1!E455 -> 0 | E22: =+Sheet1!F455 -> 0 | F22: =+Sheet1!G455 -> 0 | G22: =+Sheet1!H455 -> 0 | H22: =+Sheet1!I455 -> 0 | I22: =+Sheet1!J455 -> 0 | J22: =+Sheet1!K455 -> 0 | ... M22: =+Sheet1!N455 -> 0
A23: 20 | B23: =+Sheet1!C470 -> 21-SOOPER | C23: =+Sheet1!D490 -> 545910 | D23: =+Sheet1!E490 -> 0 | E23: =+Sheet1!F490 -> 0 | F23: =+Sheet1!G490 -> 0 | G23: =+Sheet1!H490 -> 0 | H23: =+Sheet1!I490 -> 0 | I23: =+Sheet1!J490 -> 0 | J23: =+Sheet1!K490 -> 0 | ... M23: =+Sheet1!N490 -> 0
A24: 21 | B24: =+Sheet1!C491 -> 22-VENCH | C24: =+Sheet1!D503 -> 302170 | D24: =+Sheet1!E503 -> 0 | E24: =+Sheet1!F503 -> 0 | F24: =+Sheet1!G503 -> 0 | G24: =+Sheet1!H503 -> 0 | H24: =+Sheet1!I503 -> 0 | I24: =+Sheet1!J503 -> 0 | J24: =+Sheet1!K503 -> 0 | ... M24: =+Sheet1!N503 -> 0
A25: 22 | B25: =+Sheet1!C507 -> 23- AGER MACHINE | C25: =+Sheet1!D530 -> 703530 | D25: =+Sheet1!E530 -> 0 | E25: =+Sheet1!F530 -> 0 | F25: =+Sheet1!G530 -> 0 | G25: =+Sheet1!H530 -> 0 | H25: =+Sheet1!I530 -> 0 | I25: =+Sheet1!J530 -> 0 | J25: =+Sheet1!K530 -> 0 | ... M25: =+Sheet1!N530 -> 0
A26: 23 | B26: =+Sheet1!C541 -> 24- JIGGER DYEING | C26: =+Sheet1!D561 -> 762950 | D26: =+Sheet1!E561 -> 0 | E26: =+Sheet1!F561 -> 0 | F26: =+Sheet1!G561 -> 0 | G26: =+Sheet1!H561 -> 0 | H26: =+Sheet1!I561 -> 0 | I26: =+Sheet1!J561 -> 0 | J26: =+Sheet1!K561 -> 0 | ... M26: =+Sheet1!N561 -> 0
A27: 24 | B27: =+Sheet1!C562 -> 25- JIGER DRAWING | C27: =+Sheet1!D576 -> 315678 | D27: =+Sheet1!E576 -> 0 | E27: =+Sheet1!F576 -> 0 | F27: =+Sheet1!G576 -> 0 | G27: =+Sheet1!H576 -> 0 | H27: =+Sheet1!I576 -> 0 | I27: =+Sheet1!J576 -> 0 | J27: =+Sheet1!K576 -> 0 | ... M27: =+Sheet1!N576 -> 0
A28: 25 | B28: =+Sheet1!C579 -> 26- DIGITAL MACHINE | C28: =+Sheet1!D592+Sheet1!D612+Sheet1!D632+Sheet1!D646+Sheet1!D671 -> 3557970 | D28: =+Sheet1!E592+Sheet1!E612+Sheet1!E632+Sheet1!E646+Sheet1!E671 -> 0 | E28: =+Sheet1!F592+Sheet1!F612+Sheet1!F632+Sheet1!F646+Sheet1!F671 -> 0 | F28: =+Sheet1!G592+Sheet1!G612+Sheet1!G632+Sheet1!G646+Sheet1!G671 -> 0 | G28: =+Sheet1!H592+Sheet1!H612+Sheet1!H632+Sheet1!H646+Sheet1!H671 -> 0 | H28: =+Sheet1!I592+Sheet1!I612+Sheet1!I632+Sheet1!I646+Sheet1!I671 -> 0 | I28: =+Sheet1!J592+Sheet1!J612+Sheet1!J632+Sheet1!J646+Sheet1!J671 -> 0 | J28: =+Sheet1!K592+Sheet1!K612+Sheet1!K632+Sheet1!K646+Sheet1!K671 -> 0 | ... M28: =+Sheet1!N592+Sheet1!N612+Sheet1!N632+Sheet1!N646+Sheet1!N671 -> 0
A29: 26 | B29: =+Sheet1!C688 -> 27- PPC | C29: =+Sheet1!D692 -> 127705 | D29: =+Sheet1!E692 -> 0 | E29: =+Sheet1!F692 -> 0 | F29: =+Sheet1!G692 -> 0 | G29: =+Sheet1!H692 -> 0 | H29: =+Sheet1!I692 -> 0 | I29: =+Sheet1!J692 -> 0 | J29: =+Sheet1!K692 -> 0 | ... M29: =+Sheet1!N692 -> 0
A30: 27 | B30: =+Sheet1!C698 -> 28- BOILER | C30: =+Sheet1!D702 -> 613470 | D30: =+Sheet1!E702 -> 0 | E30: =+Sheet1!F702 -> 0 | F30: =+Sheet1!G702 -> 0 | G30: =+Sheet1!H702 -> 0 | H30: =+Sheet1!I702 -> 0 | I30: =+Sheet1!J702 -> 0 | J30: =+Sheet1!K702 -> 0 | ... M30: =+Sheet1!N702 -> 0
A31: 28 | B31: =+Sheet1!C710 -> 29-GM | C31: =+Sheet1!D714 -> 330000 | D31: =+Sheet1!E714 -> 0 | E31: =+Sheet1!F714 -> 0 | F31: =+Sheet1!G714 -> 0 | G31: =+Sheet1!H714 -> 0 | H31: =+Sheet1!I714 -> 0 | I31: =+Sheet1!J714 -> 0 | J31: =+Sheet1!K714 -> 0 | ... M31: =+Sheet1!N714 -> 0
A32: 29 | B32: =+Sheet1!C724 -> 30-FOLDING | C32: =+Sheet1!D728 -> 277200 | D32: =+Sheet1!E728 -> 0 | E32: =+Sheet1!F728 -> 0 | F32: =+Sheet1!G728 -> 0 | G32: =+Sheet1!H728 -> 0 | H32: =+Sheet1!I728 -> 0 | I32: =+Sheet1!J728 -> 0 | J32: =+Sheet1!K728 -> 0 | ... M32: =+Sheet1!N728 -> 0
A33: 30 | B33: =+Sheet1!C732 -> 31-YASINE CP | C33: =+Sheet1!D736 -> 220000 | D33: =+Sheet1!E736 -> 0 | E33: =+Sheet1!F736 -> 0 | F33: =+Sheet1!G736 -> 0 | G33: =+Sheet1!H736 -> 0 | H33: =+Sheet1!I736 -> 0 | I33: =+Sheet1!J736 -> 0 | J33: =+Sheet1!K736 -> 0 | ... M33: =+Sheet1!N736 -> 0
A34: 31 | B34: =+Sheet1!C741 -> 32- ZAFAR NUG PACKING | C34: =+Sheet1!D745 -> 190000 | D34: =+Sheet1!E745 -> 0 | E34: =+Sheet1!F745 -> 0 | F34: =+Sheet1!G745 -> 0 | G34: =+Sheet1!H745 -> 0 | H34: =+Sheet1!I745 -> 0 | I34: =+Sheet1!J745 -> 0 | J34: =+Sheet1!K745 -> 0 | ... M34: =+Sheet1!N745 -> 0
A35: 32 | B35: =+Sheet1!C749 -> 33-SWEEPERS | C35: =+Sheet1!D755 -> 110000 | D35: =+Sheet1!E755 -> 0 | E35: =+Sheet1!F755 -> 0 | F35: =+Sheet1!G755 -> 0 | G35: =+Sheet1!H755 -> 0 | H35: =+Sheet1!I755 -> 0 | I35: =+Sheet1!J755 -> 0 | J35: =+Sheet1!K755 -> 0 | ... M35: =+Sheet1!N755 -> 0
A36: 33 | B36: RESIGNED | C36: 0 | D36: 0 | E36: 0 | F36: 0 | G36: 0 | H36: 0 | I36: 0 | J36: 0 | K36: 0 | L36: 0 | M36: 0
B37: TOTAL | C37: =SUM(C4:C36) -> 18315192 | D37: =SUM(D4:D36) -> 0 | E37: =SUM(E4:E36) -> 0 | F37: =SUM(F4:F36) -> 0 | G37: =SUM(G4:G36) -> 0 | H37: =SUM(H4:H36) -> 0 | I37: =SUM(I4:I36) -> 0 | J37: =SUM(J4:J36) -> 0 | ... M37: =SUM(M4:M36) -> 0
L45: IRFAN | M45: 25000
L46: ARIF | M46: 25000
L47: NSIR | M47: 20000
L48: EHSAN | M48: 15000
...

Sheet Sheet1
C3: 01-ADMINISTRAION
A4: Sr. No. | B4: NAME | C4: DESIGNATION | D4: S RATE | E4: DAYS | F4: AMOUNT | G4: HOURS | H4: AMOUNT | I4: G SALARY | J4: ADVANCE | K4: ADVANCE | L4: LOAN DED. | M4: SUITE DED. | N4: NET PAY
A5: 1 | B5: ISMAIL KHAN | C5: S Sup. | D5: 46585 | E5: 0 | F5: =+D5/31*E5 -> 0 | G5: 0 | H5: =+D5/248*G5 -> 0 | I5: =+F5+H5 -> 0 | J5: 0 | K5: 0 | L5: 0 | M5: 0 | N5: =+J5-K5-L5-M5 -> 0 | O5: 12 Hour duty + holiday over time(Sunday ect.)
A6: 2 | B6: MUSHTAQ | C6: Gate Sup. | D6: 44000 | E6: 0 | F6: =+D6/31*E6 -> 0 | G6: 0 | H6: =+D6/248*G6 -> 0 | I6: =+F6+H6 -> 0 | J6: 0 | K6: 0 | L6: 0 | M6: 0 | N6: =+J6-K6-L6-M6 -> 0 | O6: 12 Hour duty + holiday over time(Sunday ect.)
A7: 3 | B7: EHSAN ULLAH | C7: Gate Sup. | D7: 40000 | E7: 0 | F7: =+D7/31*E7 -> 0 | G7: 0 | H7: =+D7/248*G7 -> 0 | I7: =+F7+H7 -> 0 | J7: 0 | K7: 0 | L7: 0 | M7: 0 | N7: =+J7-K7-L7-M7 -> 0 | O7: 12 Hour duty + holiday over time(Sunday ect.)
A8: 4 | B8: MUHAMMAD KHALIL | C8: G S 54 | D8: 40000 | E8: 0 | F8: =+D8/31*E8 -> 0 | G8: 0 | H8: =+D8/248*G8 -> 0 | I8: =+F8+H8 -> 0 | J8: 0 | K8: 0 | L8: 0 | M8: 0 | N8: =+J8-K8-L8-M8 -> 0 | O8: 12 Hour duty + No extra days
A9: 5 | B9: FAREED BUX | C9: S/G | D9: 30000 | E9: 0 | F9: =+D9/31*E9 -> 0 | G9: 0 | H9: =+D9/248*G9 -> 0 | I9: =+F9+H9 -> 0 | J9: 0 | K9: 0 | L9: 0 | M9: 0 | N9: =+J9-K9-L9-M9 -> 0 | O9: 12 Hour duty + holiday over time(Sunday ect.)
A10: 6 | B10: SHAHID HUSSAIN | C10: Admin | D10: 54450 | E10: 0 | F10: =+D10/31*E10 -> 0 | G10: 0 | H10: =+D10/248*G10 -> 0 | I10: =+F10+H10 -> 0 | J10: 0 | K10: 0 | L10: 0 | M10: 0 | N10: =+J10-K10-L10-M10 -> 0 | O10: NO Time Limit
A11: 7 | B11: IQBAL ANWAR | C11: BARKI | D11: 36000 | E11: 0 | F11: =+D11/31*E11 -> 0 | G11: 0 | H11: =+D11/248*G11 -> 0 | I11: =+F11+H11 -> 0 | J11: 0 | K11: 0 | L11: 0 | M11: 0 | N11: =+J11-K11-L11-M11 -> 0 | O11: No in out Fixed
A12: 8 | B12: MALIK ZAMAN | C12: Stor keper | D12: 39060 | E12: 0 | F12: =+D12/31*E12 -> 0 | G12: 0 | H12: =+D12/248*G12 -> 0 | I12: =+F12+H12 -> 0 | J12: 0 | K12: 0 | L12: 0 | M12: 0 | N12: =+J12-K12-L12-M12 -> 0 | O12: 8 Hours Duty + Over time
A13: 9 | B13: AHMED KHAN | C13: Lab.Asst. | D13: 53260 | E13: 0 | F13: =+D13/31*E13 -> 0 | G13: 0 | H13: =+D13/248*G13 -> 0 | I13: =+F13+H13 -> 0 | J13: 0 | K13: 0 | L13: 0 | M13: 0 | N13: =+J13-K13-L13-M13 -> 0 | O13: 8 Hours Duty and no over time
A14: 10 | B14: M NADEEM | C14: Driver | D14: 33000 | E14: 0 | F14: =+D14/31*E14 -> 0 | G14: 0 | H14: =+D14/248*G14 -> 0 | I14: =+F14+H14 -> 0 | J14: 0 | K14: 0 | L14: 0 | M14: 0 | N14: =+J14-K14-L14-M14 -> 0 | O14: 8 Hours Duty
A15: 11 | B15: KHURAM | C15: Coal Mun. | D15: 32200 | E15: 0 | F15: =+D15/31*E15 -> 0 | G15: 0 | H15: =+D15/248*G15 -> 0 | I15: =+F15+H15 -> 0 | J15: 0 | K15: 0 | L15: 0 | M15: 0 | N15: =+J15-K15-L15-M15 -> 0 | O15: 8 Hours Duty + Over time
A16: 12 | B16: MAJID SHAH | C16: Cook | D16: 37200 | E16: 0 | F16: =+D16/31*E16 -> 0 | G16: 0 | H16: =+D16/248*G16 -> 0 | I16: =+F16+H16 -> 0 | J16: 0 | K16: 0 | L16: 0 | M16: 0 | N16: =+J16-K16-L16-M16 -> 0 | O16: NO Time Limit
A17: 13 | B17: SHEHRAZ | C17: Office Boy | D17: 33000 | E17: 0 | F17: =+D17/31*E17 -> 0 | G17: 0 | H17: =+D17/248*G17 -> 0 | I17: =+F17+H17 -> 0 | J17: 0 | K17: 0 | L17: 0 | M17: 0 | N17: =+J17-K17-L17-M17 -> 0 | O17: NO Time Limit
A18: 14 | B18: IMAM MASJID | C18: MASJID | D18: =22000+2200 -> 24200 | E18: 0 | F18: =+D18/31*E18 -> 0 | G18: 0 | H18: =+D18/248*G18 -> 0 | I18: =+F18+H18 -> 0 | J18: 0 | K18: 0 | L18: 0 | M18: 0 | N18: =+J18-K18-L18-M18 -> 0 | O18: Fixed Salary no Attendece Required
A19: 15 | B19: MAQBOOL | C19: S/MAN | D19: 16000 | E19: 0 | F19: =+D19/31*E19 -> 0 | G19: 0 | H19: =+D19/248*G19 -> 0 | I19: =+F19+H19 -> 0 | J19: 0 | K19: 0 | L19: 0 | M19: 0 | N19: =+J19-K19-L19-M19 -> 0 | O19: Fixed Salary no Attendece Required
B20: TOTAL | D20: =SUM(D5:D19) -> 558955 | E20: =SUM(E5:E19) -> 0 | F20: =SUM(F5:F19) -> 0 | G20: =SUM(G5:G19) -> 0 | H20: =SUM(H5:H19) -> 0 | I20: =SUM(I5:I19) -> 0 | J20: =SUM(J5:J19) -> 0 | K20: =SUM(K5:K19) -> 0 | ... N20: =SUM(N5:N19) -> 0
C23: 02- ACCOUNT
A24: Sr. No. | B24: NAME | C24: DESIGNATION | D24: S RATE | E24: DAYS | F24: AMOUNT | G24: HOURS | H24: AMOUNT | I24: G SALARY | J24: ADVANCE | K24: ADVANCE | L24: LOAN DED. | M24: SUITE DED. | N24: NET PAY
A25: 1 | B25: TARIQ SAEED | C25: Manager | D25: 110000 | E25: 0 | F25: =+D25/31*E25 -> 0 | G25: 0 | H25: =+D25/248*G25 -> 0 | I25: =+F25+H25 -> 0 | J25: 0 | K25: 0 | L25: 0 | M25: 0 | N25: =+J25-K25-L25-M25 -> 0 | O25: 8 Hours Duty
A26: 2 | B26: TARIQ JAMIL | C26: Accountant | D26: 97829 | E26: 0 | F26: =+D26/31*E26 -> 0 | G26: 0 | H26: =+D26/248*G26 -> 0 | I26: =+F26+H26 -> 0 | J26: 0 | K26: 0 | L26: 0 | M26: 0 | N26: =+J26-K26-L26-M26 -> 0 | O26: 8 Hours Duty
A27: 3 | B27: M AZAM | C27: Purchser | D27: 102850 | E27: 0 | F27: =+D27/31*E27 -> 0 | G27: 0 | H27: =+D27/248*G27 -> 0 | I27: =+F27+H27 -> 0 | J27: 0 | K27: 0 | L27: 0 | M27: 0 | N27: =+J27-K27-L27-M27 -> 0 | O27: 8 Hours Duty
A28: 4 | B28: KASHIF JAVAID | C28: Manager | D28: 110000 | E28: 0 | F28: =+D28/31*E28 -> 0 | G28: 0 | H28: =+D28/248*G28 -> 0 | I28: =+F28+H28 -> 0 | J28: 0 | K28: 0 | L28: 0 | M28: 0 | N28: =+J28-K28-L28-M28 -> 0 | O28: 8 Hours Duty
A29: 5 | B29: RANA TAJAMAL | C29: Accountant | D29: 45250 | E29: 0 | F29: =+D29/31*E29 -> 0 | G29: 0 | H29: =+D29/248*G29 -> 0 | I29: =+F29+H29 -> 0 | J29: 0 | K29: 0 | L29: 0 | M29: 0 | N29: =+J29-K29-L29-M29 -> 0 | O29: 8 Hours Duty
A30: 6 | B30: IRFAN AKHTER | C30: Accountant | D30: 59230 | E30: 0 | F30: =+D30/31*E30 -> 0 | G30: 0 | H30: =+D30/248*G30 -> 0 | I30: =+F30+H30 -> 0 | J30: 0 | K30: 0 | L30: 0 | M30: 0 | N30: =+J30-K30-L30-M30 -> 0 | O30: 8 Hours Duty
A31: 7 | B31: AHMED RAZA | C31: Accountant | D31: 57640 | E31: 0 | F31: =+D31/31*E31 -> 0 | G31: 0 | H31: =+D31/248*G31 -> 0 | I31: =+F31+H31 -> 0 | J31: 0 | K31: 0 | L31: 0 | M31: 0 | N31: =+J31-K31-L31-M31 -> 0 | O31: 8 Hours Duty
A32: 8 | B32: WAQAS | C32: Accountant | D32: 50000 | E32: 0 | F32: =+D32/31*E32 -> 0 | G32: 0 | H32: =+D32/248*G32 -> 0 | I32: =+F32+H32 -> 0 | J32: 0 | K32: 0 | L32: 0 | M32: 0 | N32: =+J32-K32-L32-M32 -> 0 | O32: 8 Hours Duty
A33: 9 | B33: TOQEER | C33: Asist. | D33: 28000 | E33: 0 | F33: =+D33/31*E33 -> 0 | G33: 0 | H33: =+D33/248*G33 -> 0 | I33: =+F33+H33 -> 0 | J33: 0 | K33: 0 | L33: 0 | M33: 0 | N33: =+J33-K33-L33-M33 -> 0 | O33: 8 Hours Duty
A34: 10 | B34: ASIF | C34: SOFT WEAR | D34: 25000 | E34: 0 | F34: =+D34/31*E34 -> 0 | G34: 0 | H34: =+D34/248*G34 -> 0 | I34: =+F34+H34 -> 0 | J34: 0 | K34: 0 | L34: 0 | M34: 0 | N34: =+J34-K34-L34-M34 -> 0 | O34: Fixed Salary no Attendece Required
B35: TOTAL | D35: =SUM(D25:D34) -> 685799 | E35: =SUM(E25:E34) -> 0 | F35: =SUM(F25:F34) -> 0 | G35: =SUM(G25:G34) -> 0 | H35: =SUM(H25:H34) -> 0 | I35: =SUM(I25:I34) -> 0 | J35: =SUM(J25:J34) -> 0 | K35: =SUM(K25:K34) -> 0 | ... N35: =SUM(N25:N34) -> 0
C41: 03-KORA
A42: Sr. No. | B42: NAME | C42: DESIGNATION | D42: S RATE | E42: DAYS | F42: AMOUNT | G42: HOURS | H42: AMOUNT | I42: G SALARY | J42: ADVANCE | K42: ADVANCE | L42: LOAN DED. | M42: SUITE DED. | N42: NET PAY
A43: 1 | B43: SAJID ALI | C43: Incharge | D43: 73200 | E43: 0 | F43: =+D43/31*E43 -> 0 | G43: 0 | H43: =+D43/248*G43 -> 0 | I43: =+F43+H43 -> 0 | J43: 0 | K43: 0 | L43: 0 | M43: 0 | N43: =+J43-K43-L43-M43 -> 0 | O43: 8 Hours Duty
A44: 2 | B44: NISAR | C44: Asist. | D44: =56360+5000 -> 61360 | E44: 0 | F44: =+D44/31*E44 -> 0 | G44: 0 | H44: =+D44/248*G44 -> 0 | I44: =+F44+H44 -> 0 | J44: 0 | K44: 0 | L44: 0 | M44: 0 | N44: =+J44-K44-L44-M44 -> 0 | O44: 8 Hours Duty + Over time
A45: 3 | B45: RIAZ | C45: S/Man | D45: 38650 | E45: 0 | F45: =+D45/31*E45 -> 0 | G45: 0 | H45: =+D45/248*G45 -> 0 | I45: =+F45+H45 -> 0 | J45: 0 | K45: 0 | L45: 0 | M45: 0 | N45: =+J45-K45-L45-M45 -> 0 | O45: 8 Hours Duty + Over time
A46: 4 | B46: SAJJAD | C46: S/Man | D46: 38650 | E46: 0 | F46: =+D46/31*E46 -> 0 | G46: 0 | H46: =+D46/248*G46 -> 0 | I46: =+F46+H46 -> 0 | J46: 0 | K46: 0 | L46: 0 | M46: 0 | N46: =+J46-K46-L46-M46 -> 0 | O46: 8 Hours Duty + Over time
A47: 5 | B47: FAISAL | C47: Mark Man | D47: 29700 | E47: 0 | F47: =+D47/31*E47 -> 0 | G47: 0 | H47: =+D47/248*G47 -> 0 | I47: =+F47+H47 -> 0 | J47: 0 | K47: 0 | L47: 0 | M47: 0 | N47: =+J47-K47-L47-M47 -> 0 | O47: 8 Hours Duty + Over time
A48: 6 | B48: IJAZ | C48: P/Man | D48: 25000 | E48: 0 | F48: =+D48/31*E48 -> 0 | G48: 0 | H48: =+D48/248*G48 -> 0 | I48: =+F48+H48 -> 0 | J48: 0 | K48: 0 | L48: 0 | M48: 0 | N48: =+J48-K48-L48-M48 -> 0 | O48: 8 Hours Duty + Over time
A49: 7 | B49: RASHID | C49: P/Man | D49: 25000 | E49: 0 | F49: =+D49/31*E49 -> 0 | G49: 0 | H49: =+D49/248*G49 -> 0 | I49: =+F49+H49 -> 0 | J49: 0 | K49: 0 | L49: 0 | M49: 0 | N49: =+J49-K49-L49-M49 -> 0 | O49: 8 Hours Duty + Over time
...
